Workbook

Sheet Tables
A1: Person ID | B1: Average Natural Spending | D1: Person ID | E1: Average of amount | H1: gender | I1: age | J1: id | K1: became_member_on | L1: income | M1: avg_natural_spending | N1: offer_sensibility | O1: member_for_days | P1: Segment | Q1: member_years | R1: member_years_group | S1: In thousands
A2: 0009655768c64bdeb2e877511632db8f | B2: 16.145 | D2: 0009655768c64bdeb2e877511632db8f | E2: 15.95 | H2: M | I2: 43 | J2: bf8d7498eb32431ab3fedaa14b7d3a0d | K2: 42993 | L2: 70000 | M2: 0 | N2: 0 | O2: 319 | P2: Occasionals | Q2: 0.87 | R2: 0-1 | S2: =profile[[#This Row],[income]]/1000 -> 70
A3: 0020c2b971eb4e9188eac86d93036a77 | B3: 26.9983 | D3: 0020c2b971eb4e9188eac86d93036a77 | E3: 24.6075 | H3: M | I3: 68 | J3: c863af14b3654499b1caea5e640136d2 | K3: 43138 | L3: 58000 | M3: 0 | N3: 0 | O3: 174 | P3: Occasionals | Q3: 0.48 | R3: 0-1 | S3: =profile[[#This Row],[income]]/1000 -> 58
A4: 0020ccbbb6d84e358d3414a3ff76cffd | B4: 11.736 | D4: 0020ccbbb6d84e358d3414a3ff76cffd | E4: 12.8375 | H4: M | I4: 52 | J4: 5f18c5754dc04baaa1267c823f877a85 | K4: 43285 | L4: 42000 | M4: 0 | N4: 0 | O4: 27 | P4: Occasionals | Q4: 0.07 | R4: 0-1 | S4: =profile[[#This Row],[income]]/1000 -> 42
A5: 003d66b6608740288d6cc97a6903f4f0 | B5: 2.9033 | D5: 003d66b6608740288d6cc97a6903f4f0 | E5: 2.6855556 | H5: M | I5: 81 | J5: accec36a10704e1fbaeb9b28b8bc5da8 | K5: 43223 | L5: 93000 | M5: 0 | N5: 0 | O5: 89 | P5: Occasionals | Q5: 0.24 | R5: 0-1 | S5: =profile[[#This Row],[income]]/1000 -> 93
A6: 00426fe3ffde4c6b9cb9ad6d077a13ea | B6: 2.1389 | D6: 00426fe3ffde4c6b9cb9ad6d077a13ea | E6: 4.03 | H6: M | I6: 41 | J6: 031387fa9cfd47e88f4e4b4b4cb71925 | K6: 43000 | L6: 83000 | M6: 0 | N6: 0 | O6: 312 | P6: Occasionals | Q6: 0.85 | R6: 0-1 | S6: =profile[[#This Row],[income]]/1000 -> 83
A7: 004b041fbfe44859945daa2c7f79ee64 | B7: 22.6275 | D7: 004b041fbfe44859945daa2c7f79ee64 | E7: 23.06 | H7: M | I7: 64 | J7: 66ccb31b29da4e9db3337fcfd5039c17 | K7: 43163 | L7: 67000 | M7: 0 | N7: 0 | O7: 149 | P7: Occasionals | Q7: 0.41 | R7: 0-1 | S7: =profile[[#This Row],[income]]/1000 -> 67
A8: 004c5799adbf42868b9cff0396190900 | B8: 27.2711 | D8: 004c5799adbf42868b9cff0396190900 | E8: 28.948333 | H8: M | I8: 49 | J8: 1e78f244cac34e758dff086f30dbc1be | K8: 43062 | L8: 39000 | M8: 0 | N8: 0 | O8: 250 | P8: Occasionals | Q8: 0.68 | R8: 0-1 | S8: =profile[[#This Row],[income]]/1000 -> 39
A9: 005500a7188546ff8a767329a2f7c76a | B9: 0 | D9: 005500a7188546ff8a767329a2f7c76a | E9: 5.09 | H9: M | I9: 41 | J9: acc3bb69130c45aca141e8aa86f41b42 | K9: 43032 | L9: 55000 | M9: 0 | N9: 0 | O9: 280 | P9: Occasionals | Q9: 0.77 | R9: 0-1 | S9: =profile[[#This Row],[income]]/1000 -> 55
A10: 0056df74b63b4298809f0b375a304cf4 | B10: 28.74 | D10: 0056df74b63b4298809f0b375a304cf4 | E10: 28.828 | H10: M | I10: 19 | J10: 80712efd45a84787b08074798ac40429 | K10: 43275 | L10: 32000 | M10: 0 | N10: 0 | O10: 37 | P10: Occasionals | Q10: 0.1 | R10: 0-1 | S10: =profile[[#This Row],[income]]/1000 -> 32
A11: 00715b6e55c3431cb56ff7307eb19675 | B11: 25.008 | D11: 00715b6e55c3431cb56ff7307eb19675 | E11: 25.008 | H11: M | I11: 47 | J11: 8b5f5a1b1c43427ba7fb1e8e307a05e3 | K11: 43048 | L11: 44000 | M11: 0 | N11: 0 | O11: 264 | P11: Occasionals | Q11: 0.72 | R11: 0-1 | S11: =profile[[#This Row],[income]]/1000 -> 44
A12: 0082fd87c18f45f2be70dbcbb0fb8aad | B12: 15.63 | D12: 0082fd87c18f45f2be70dbcbb0fb8aad | E12: 17.407143 | H12: M | I12: 39 | J12: 30f768e59835437d86743fd5daad69e3 | K12: 43244 | L12: 71000 | M12: 0 | N12: 0 | O12: 68 | P12: Occasionals | Q12: 0.19 | R12: 0-1 | S12: =profile[[#This Row],[income]]/1000 -> 71
A13: 00840a2ca5d2408e982d56544dc14ffd | B13: 3.4583 | D13: 00840a2ca5d2408e982d56544dc14ffd | E13: 3.7017647 | H13: M | I13: 57 | J13: 05ad6da25fcf4ea483562a4233cc345f | K13: 42953 | L13: 33000 | M13: 0 | N13: 0 | O13: 359 | P13: Occasionals | Q13: 0.98 | R13: 0-1 | S13: =profile[[#This Row],[income]]/1000 -> 33
... A14143: f7e4e1ccb570482b8c2eed7622663ad2 | B14143: 4.625 | D14143: ffff82501cea40309d5fdd7edcca4a07 | E14143: 15.071333 | H14143: M | I14143: 63 | J14143: db564686d31c48e4b35a4ee0ce50f824 | K14143: 43306 | L14143: 56000 | M14143: 12.592 | N14143: 0 | O14143: 6 | P14143: Occasionals | Q14143: 0.02 | R14143: 0-1 | S14143: =profile[[#This Row],[income]]/1000 -> 56
A14144: f7e5b4482f474c70a3be6e95fb04481a | B14144: 10.162 | H14144: M | I14144: 51 | J14144: 074e7e5b342a4254ad649dc6aeb6fa04 | K14144: 43200 | L14144: 53000 | M14144: 8.055 | N14144: 0 | O14144: 112 | P14144: Occasionals | Q14144: 0.31 | R14144: 0-1 | S14144: =profile[[#This Row],[income]]/1000 -> 53
A14145: f7ebbbab571d44ec883575b11009be2f | B14145: 3.08 | H14145: M | I14145: 43 | J14145: 3cdf490843d244fead8d84dd2ab599df | K14145: 43121 | L14145: 52000 | M14145: 8.02 | N14145: 0 | O14145: 191 | P14145: Occasionals | Q14145: 0.52 | R14145: 0-1 | S14145: =profile[[#This Row],[income]]/1000 -> 52
A14146: f7f8edca3380473b9acc9994c72d9e80 | B14146: 3.54 | H14146: M | I14146: 34 | J14146: d5929c3cb705407aaa4a1f2730f3ee7a | K14146: 43193 | L14146: 65000 | M14146: 4.57 | N14146: 0 | O14146: 119 | P14146: Occasionals | Q14146: 0.33 | R14146: 0-1 | S14146: =profile[[#This Row],[income]]/1000 -> 65
A14147: f7fca0d04d8d4416ae5c21510247d106 | B14147: 26.6967 | H14147: M | I14147: 70 | J14147: effcc502e92d4e16851a085bd7fe2c03 | K14147: 43222 | L14147: 59000 | M14147: 0.79 | N14147: 0 | O14147: 90 | P14147: Occasionals | Q14147: 0.25 | R14147: 0-1 | S14147: =profile[[#This Row],[income]]/1000 -> 59
A14148: f7fe5a1f9cbf455495d8a29aac7d29d6 | B14148: 4.04 | H14148: M | I14148: 51 | J14148: b970d698e4e9401499f576ff968b8c7d | K14148: 42953 | L14148: 73000 | M14148: 2.4325 | N14148: 0 | O14148: 359 | P14148: Occasionals | Q14148: 0.98 | R14148: 0-1 | S14148: =profile[[#This Row],[income]]/1000 -> 73
A14149: f7ff56f770734474af6f7da423f764da | B14149: 20.17 | H14149: M | I14149: 54 | J14149: 950ece4963a84efd9dcc17d007f60634 | K14149: 43198 | L14149: 41000 | M14149: 2.1933 | N14149: 0 | O14149: 114 | P14149: Occasionals | Q14149: 0.31 | R14149: 0-1 | S14149: =profile[[#This Row],[income]]/1000 -> 41
A14150: f8049ce7e45445ba8bd28204bcce33b2 | B14150: 4.9 | H14150: M | I14150: 52 | J14150: 6cc7905aff274c08be9a1424bf2d1342 | K14150: 43018 | L14150: 37000 | M14150: 3.1533 | N14150: 0 | O14150: 294 | P14150: Occasionals | Q14150: 0.8 | R14150: 0-1 | S14150: =profile[[#This Row],[income]]/1000 -> 37
A14151: f806632c011441378d4646567f357a21 | B14151: 16.02 | H14151: M | I14151: 66 | J14151: 7285ee7e1e824b4c9914f3245bb4839c | K14151: 43193 | L14151: 44000 | M14151: 2.495 | N14151: 0 | O14151: 119 | P14151: Occasionals | Q14151: 0.33 | R14151: 0-1 | S14151: =profile[[#This Row],[income]]/1000 -> 44
A14152: f80c230bcb8f483cb66dd0e2a28af129 | B14152: 3.04 | H14152: M | I14152: 39 | J14152: eb63ed97866b4e93b27a9ad9a0924458 | K14152: 42990 | L14152: 57000 | M14152: 4.18 | N14152: 0 | O14152: 322 | P14152: Occasionals | Q14152: 0.88 | R14152: 0-1 | S14152: =profile[[#This Row],[income]]/1000 -> 57
A14153: f80eb9caef944ca899f2bef52b6c2f5e | B14153: 0 | H14153: M | I14153: 43 | J14153: cdf092b0296c48f1a940e45dc778ddaf | K14153: 43006 | L14153: 63000 | M14153: 0.43 | N14153: 0 | O14153: 306 | P14153: Occasionals | Q14153: 0.84 | R14153: 0-1 | S14153: =profile[[#This Row],[income]]/1000 -> 63
A14154: f817370b73334e6692ea184342983684 | B14154: 15.93 | H14154: M | I14154: 61 | J14154: 8dc17515545e42d9a2974a3aebc3aa69 | K14154: 43259 | L14154: 43000 | M14154: 3.98 | N14154: 0 | O14154: 53 | P14154: Occasionals | Q14154: 0.15 | R14154: 0-1 | S14154: =profile[[#This Row],[income]]/1000 -> 43
A14155: f8174da75bf34ecdbc526b3cb8345f21 | B14155: 3.66 | H14155: M | I14155: 86 | J14155: f9df4a32439047ddb7378321a4556409 | K14155: 43138 | L14155: 36000 | M14155: 3.0167 | N14155: 0 | O14155: 174 | P14155: Occasionals | Q14155: 0.48 | R14155: 0-1 | S14155: =profile[[#This Row],[income]]/1000 -> 36
... A14468: fd700397b7c8440baa70d5539926c5a0 | B14468: 12.7 | H14468: M | I14468: 61 | J14468: 2cb4f97358b841b9a9773a7aa05a9d77 | K14468: 43294 | L14468: 72000 | M14468: 3.71 | N14468: 0 | O14468: 18 | P14468: Occasionals | Q14468: 0.05 | R14468: 0-1 | S14468: =profile[[#This Row],[income]]/1000 -> 72
A14469: fd72dcc657a744e1b3ac0501910fc2f8 | B14469: 25.4557
A14470: fd75302f189044e083f32152398889c5 | B14470: 14.9725
A14471: fd77e2de07bc4c2bb93399f5d765198a | B14471: 19.004
A14472: fd7ac6a24ecd4f9c87e1a0423e2d975d | B14472: 3.48
A14473: fd7ed8ba5ae84ceba227970f2243fad3 | B14473: 4.878
A14474: fd86891799d1426584d7735b45da5481 | B14474: 17.126
A14475: fd8866c398944d05be7306dfbe3c3508 | B14475: 8.686
A14476: fd8df348b1e8406aaa0cce96510c5eaa | B14476: 3.89
A14477: fd90af4b9b784b268efa9d349a762491 | B14477: 13.6614
A14478: fd91690fcf5b477aa5b5bdedb238e907 | B14478: 15.88
A14479: fd988b3d7dac4453adf3ba0deec5fba6 | B14479: 0
A14480: fd98c46aa9c742b1a5369c1cf18b5705 | B14480: 4.29
... A14614: ffff82501cea40309d5fdd7edcca4a07 | B14614: 14.0009
...

Sheet Calculations
A1: User Inputs | E1: Results
A2: Budget | B2: =Dashboard!CS7 -> 20000 | E2: Simulated Conv. Rate) | F2: =F19*(1+B5) -> 0.70299003
A3: Segment | B3: =Dashboard!AA7 -> Deal Hunters | E3: Expected offers | F3: =MIN(B25:B26) -> 4986 | G3: =IF(F3>=F26,"(Max)","") -> (Max)
A4: Offer type | B4: =Dashboard!BL7 -> discount | E4: Expected Conversions | F4: =_xlfn.FLOOR.MATH(F3*F2) -> 3505
A5: Stress Factor Conversion | B5: =(F25-20)/100 -> 0 | E5: Expected Revenue | F5: =F4*F10 -> 86065.376
A6: Stress Factor Avereage Spent | B6: =(F27-20)/100 -> 0.1 | E6: Expected Cost | F6: =F3*F21 -> 14401.999
E7: Expected Profit | F7: =F5-F6 -> 71663.377
E8: Budget Left | F8: =B2-F6 -> 5598.0014
E9: Expected ROI | F9: =(F5-F6)/F6 -> 4.9759328
E10: Simulated promo spent | F10: =F20*(1+B6) -> 24.555029
E11: Simulated natural spent | F11: =F22*(1+B6) -> 22.891512
E12: Incremental Revenue | F12: =F4*(F10-F11) -> 5830.6257
A17: Calculations
A18: Segments | B18: Target Users | C18: Offer Type | E18: Metrics | H18: Waterfall Chart
A19: Brand Loyalists | B19: 5000 | C19: bogo | E19: Conversion Rate | F19: =CUBEVALUE("ThisWorkbookDataModel", "[Measures].[Conversion Rate]", "[profile].[Segment].["& $B$3 &"]", "[portfolio].[offer_type].["& $B$4 &"]") -> 0.70299003 | H19: Category | I19: Value
A20: Deal Hunters | B20: 10000 | C20: discount | E20: Average promo spent | F20: =CUBEVALUE("ThisWorkbookDataModel", "[Measures].[Average spent (during offers)]]", "[profile].[Segment].["& $B$3 &"]", "[portfolio].[offer_type].["& $B$4 &"]") -> 22.322753 | H20: Natural Spent | I20: =F4*F11 -> 80234.75
A21: Promo Driven | B21: 15000 | E21: Average reward | F21: =CUBEVALUE("ThisWorkbookDataModel", "[Measures].[Average Reward]]", "[profile].[Segment].["& $B$3 &"]", "[portfolio].[offer_type].["& $B$4 &"]") -> 2.8884875 | H21: Incremental Revenue | I21: =F12 -> 5830.6257
A22: Occasionals | B22: 20000 | E22: Average natural spent | F22: =CUBEVALUE("ThisWorkbookDataModel", "[Measures].[Average spent (outside offers)]", "[profile].[Segment].["& $B$3 &"]", "[portfolio].[offer_type].["& $B$4 &"]") -> 20.810466 | H22: Cost | I22: =-F6 -> -14401.999
E23: ROAS | F23: =CUBEVALUE("ThisWorkbookDataModel", "[Measures].[ROAS (adjusted)]", "[profile].[Segment].["& $B$3 &"]", "[portfolio].[offer_type].["& $B$4 &"]") -> 5.4292571 | H23: Profit | I23: =F7 -> 71663.377
A24: Sendable offers | E24: Total transactions | F24: =CUBEVALUE("ThisWorkbookDataModel", "[Measures].[Total Transactions (during offers)]", "[profile].[Segment].["& $B$3 &"]", "[portfolio].[offer_type].["& $B$4 &"]") -> 16441
A25: Financia limit | B25: =_xlfn.FLOOR.MATH(B2/F21) -> 6924 | E25: Stress factor (conv.) | F25: 20
A26: Physical limit | B26: =F26 -> 4986 | E26: Population | F26: =CUBEVALUE("ThisWorkbookDataModel", "[Measures].[Total Users]", "[profile].[Segment].["& B3 &"]") -> 4986
E27: Stress factor (spent) | F27: 30
A31: Dynamic data table
A32: =C32*0.6 -> 12000 | B32: =C32*0.8 -> 16000 | C32: =B2 -> 20000 | D32: =C32*(1.2) -> 24000 | E32: =C32*(1.4) -> 28000
A35: Conv.Rate / Profit
A36: =Calculations!F7 -> 71663.377 | B36: 12000 | C36: 16000 | D36: 20000 | E36: 24000 | F36: 28000
A37: -0.2 | B37: 45361.77 | C37: 54450.302 | D37: 54450.302 | E37: 54450.302 | F37: 54450.302
A38: -0.15 | B38: 48946.805 | C38: 58747.432 | D38: 58747.432 | E38: 58747.432 | F38: 58747.432
A39: -0.1 | B39: 52531.839 | C39: 63044.562 | D39: 63044.562 | E39: 63044.562 | F39: 63044.562
A40: -0.05 | B40: 56116.873 | C40: 67341.692 | D40: 67341.692 | E40: 67341.692 | F40: 67341.692
A41: 0 | B41: 59701.907 | C41: 71663.377 | D41: 71663.377 | E41: 71663.377 | F41: 71663.377
A42: 0.05 | B42: 63286.941 | C42: 75960.508 | D42: 75960.508 | E42: 75960.508 | F42: 75960.508
A43: 0.1 | B43: 66871.976 | C43: 80257.638 | D43: 80257.638 | E43: 80257.638 | F43: 80257.638
A44: 0.15 | B44: 70457.01 | C44: 84554.768 | D44: 84554.768 | E44: 84554.768 | F44: 84554.768
A45: 0.2 | B45: 74042.044 | C45: 88876.453 | D45: 88876.453 | E45: 88876.453 | F45: 88876.453

Sheet EDA
AC3: Funnel
AC4: Event | AD4: Offer | AE4: As % | AH4: Key Metrics
AC5: Total received offers | AD5: 64932 | AE5: =AD5/$AD$5 -> 1 | AH5: Revenue (adjusted) | AI5: 418761.04
AC6: Total viewed offers | AD6: 48566 | AE6: =AD6/$AD$5 -> 0.7479517 | AH6: Average spent (during offers) | AI6: 11.677577
AC7: Total completed offers | AD7: 31493 | AE7: =AD7/$AD$5 -> 0.48501509 | AH7: Revenue (overall) | AI7: 1590900.7
AC8: Total completed offers (intentional) | AD8: 21850 | AE8: =AD8/$AD$5 -> 0.33650588 | AH8: Revenue (during offers) | AI8: 623022.09
AH9: Revenue (outside offers) | AI9: 967878.65
AH10: Total Cost | AI10: 155655
AH11: ROAS (adjusted) | AI11: 1.994109
AH12: Total completed offers (intentional) | AI12: 21850
AH13: Total completed offers | AI13: 31493
AH14: Average spent (outside offers) | AI14: 14.330027
AH15: Total Transactions (during offers) | AI15: 53352
AH16: Total received offers | AI16: 64932
B17: 99 percentile | C17: =_xlfn.PERCENTILE.INC(Tables!B2:B14614,0.99) -> 68.678824 | AC17: Gender | AD17: People Count | AH17: Incremental Revenue (corrected) | AI17: 21709.354
AC18: Female | AD18: 0.41909173
AC19: Male | AD19: 0.58090827
AC20: Grand Total | AD20: 1
AC22: Gender | AD22: People Count
AC23: 0-1 | AD23: 7360
AC24: 1-3 | AD24: 5784 | AH24: Segments | AI24: Promo Dependency | AJ24: Net Margin % | AK24: ROAS (adjusted) | AL24: Average spent (outside offers) | AM24: Average spent (during offers) | AN24: Total Transactions (during offers) | AO24: Total Transactions (outside offers) | AP24: Distinct Count of person | AQ24: Incremental Revenue (corrected)
AC25: 3+ | AD25: 1323 | AH25: Brand Loyalists | AI25: 0.22274029 | AJ25: 0.58762454 | AK25: 1.1150367 | AL25: 21.430941 | AM25: 20.50141 | AN25: 2723 | AO25: 9502 | AP25: 0.1537972 | AQ25: -2531.1119
AC26: Grand Total | AD26: 14467 | AH26: Deal Hunters | AI26: 0.37045967 | AJ26: 0.76798623 | AK26: 2.5961918 | AL26: 20.810466 | AM26: 22.322753 | AN26: 16441 | AO26: 27939 | AP26: 0.35256682 | AQ26: 24863.524
AH27: Occasionals | AI27: 0.56923987 | AJ27: 0.81372469 | AK27: 0.98206402 | AL27: 4.7701463 | AM27: 4.1042611 | AN27: 19246 | AO27: 14564 | AP27: 0.31424127 | AQ27: -12815.625
AC28: Offer sensibility quartiles | AH28: Promo Driven | AI28: 0.49023918 | AJ28: 0.72962369 | AK28: 1.5015826 | AL28: 7.2952204 | AM28: 8.1112134 | AN28: 14942 | AO28: 15537 | AP28: 0.17939471 | AQ28: 12192.566
AC29: Sensibility value | AD29: Customers | AH29: Grand Total | AI29: 0.44131222 | AJ29: 0.75016135 | AK29: 1.994109 | AL29: 14.330027 | AM29: 11.677577 | AN29: 53352 | AO29: 67542 | AP29: 1 | AQ29: 21709.354
AC30: =_xlfn.PERCENTILE.INC(profile[offer_sensibility],0.25) -> 0 | AD30: =COUNTIFS(profile[offer_sensibility],"<=" &AC30) -> 3897
AC31: =_xlfn.PERCENTILE.INC(profile[offer_sensibility],0.5) -> 0.4 | AD31: =COUNTIFS(profile[offer_sensibility], "<=" &AC31, profile[offer_sensibility], ">"&AC30) -> 3659
AC32: =_xlfn.PERCENTILE.INC(profile[offer_sensibility],0.75) -> 0.67 | AD32: =COUNTIFS(profile[offer_sensibility], "<=" &AC32, profile[offer_sensibility], ">"&AC31) -> 3815
AC33: =_xlfn.PERCENTILE.INC(profile[offer_sensibility],1) -> 1 | AD33: =COUNTIFS(profile[offer_sensibility], "<=" &AC33, profile[offer_sensibility], ">"&AC32) -> 3096
AC35: Row Labels | AD35: Average spent (during offers) | AE35: Average spent (outside offers)
AC36: Brand Loyalists | AD36: 20.50141 | AE36: 21.430941
AC37: Deal Hunters | AD37: 22.322753 | AE37: 20.810466
AC38: Occasionals | AD38: 4.1042611 | AE38: 4.7701463
AC39: Promo Driven | AD39: 8.1112134 | AE39: 7.2952204
AC40: Grand Total | AD40: 11.677577 | AE40: 14.330027

Sheet Dashboard
AA7: Deal Hunters | BL7: discount | CS7: 20000
CS23: =Calculations!B5 -> 0
CS25: =Calculations!B6 -> 0.1
